<?xml version="1.0" ?>
<!-- =================================================================================== -->
<!-- |    This document was autogenerated by xacro from arm_robot.xacro                | -->
<!-- |    EDITING THIS FILE BY HAND IS NOT RECOMMENDED                                 | -->
<!-- =================================================================================== -->
<robot name="Finder_arm" xmlns:xacro="http://www.ros.org/wiki/xacro">
  <!--materials-->
  <material name="Black">
    <color rgba="0.0 0.0 0.0 1.0"/>
  </material>
  <material name="Red">
    <color rgba="0.8 0.0 0.0 1.0"/>
  </material>
  <material name="White">
    <color rgba="1.0 1.0 1.0 1.0"/>
  </material>
  <propert name="deg_to_rad" value="0.0174532925199432957"/>
  <!--botton fixed link-->
  <joint name="bottom_joint" type="fixed">
    <origin rpy="0 0 0 " xyz="0 0 0"/>
    <parent link="base_link"/>
    <child link="bottom_link"/>
  </joint>
  <link name="bottom_link">
    <visual>
      <origin rpy="0 0 0" xyz="0 0 -0.04"/>
      <geometry>
        <box size="1 1 0.02"/>
      </geometry>
      <material name="Brown"/>
    </visual>
    <collision>
      <origin rpy="0 0 0" xyz="0 0 -0.04"/>
      <geometry>
        <box size="1 1 0.02"/>
      </geometry>
    </collision>
  </link>
  <gazebo reference="bottom_link">
    <material> Gazebo/White </material>
  </gazebo>
  <!--base_link-->
  <link name="base_link">
    <visual>
      <origin rpy="1.570795 0 0" xyz="0 0 0"/>
      <geometry>
        <box size="0.1 0.1 0.1"/>
      </geometry>
      <material name="White"/>
    </visual>
    <collision>
      <origin rpy="1.570795 0 0" xyz="0 0 0"/>
      <geometry>
        <box size="0.1 0.1 0.1"/>
      </geometry>
    </collision>
    <inertial>
      <mass value="1"/>
      <inertia ixx="1.0" ixy="0.0" ixz="0.0" iyy="0.5" iyz="0.0" izz="1.0"/>
    </inertial>
  </link>
  <gazebo reference="base_link">
    <material> Gazebo/White </material>
  </gazebo>
  <joint name="shoulder_pan_joint" type="revolute">
    <parent link="base_link"/>
    <child link="shoulder_pan_link"/>
    <origin rpy="0 1.570795 0.0" xyz="0 0 0.05"/>
    <axis xyz="-1 0 0"/>
    <limit effort="300" lower="-2.61799387799" upper="1.9839484856" velocity="1"/>
    <dynamics damping="50" friction="1"/>
  </joint>
  <!--shoulder pan_link-->
  <link name="shoulder_pan_link">
    <visual>
      <origin rpy="0 1.570795 0" xyz="0 0 0"/>
      <geometry>
        <cylinder length="0.08" radius="0.04"/>
      </geometry>
      <material name="Red"/>
    </visual>
    <collision>
      <origin rpy="0 1.570795 0" xyz="0 0 0"/>
      <geometry>
        <cylinder length="0.08" radius="0.04"/>
      </geometry>
    </collision>
    <inertial>
      <mass value="1"/>
      <inertia ixx="1.0" ixy="0.0" ixz="0.0" iyy="0.5" iyz="0.0" izz="1.0"/>
    </inertial>
  </link>
  <gazebo reference="shoulder_pan_link">
    <material>Gazebo/Red </material>
  </gazebo>
  <joint name="shoulder_pitch_joint" type="revolute">
    <parent link="shoulder_pan_link"/>
    <child link="shoulder_pitch_link"/>
    <origin rpy="-1.570795 0 1.570795" xyz="-0.08 0.0021 0.0"/>
    <axis xyz="1 0 0"/>
    <limit effort="300" lower="-1.19962513147" upper="1.89994105047" velocity="1"/>
    <dynamics damping="50" friction="1"/>
  </joint>
  <!-- shoulder pich link-->
  <link name="shoulder_pitch_link">
    <visual>
      <origin rpy="0 1.570795 0" xyz="-0.002 0 0.18"/>
      <geometry>
        <box size="0.4 0.04 0.04"/>
      </geometry>
      <material name="White"/>
    </visual>
    <collision>
      <origin rpy="0 1.570795 0" xyz="-0.002 0 0.18"/>
      <geometry>
        <box size="0.4 0.04 0.04"/>
      </geometry>
    </collision>
    <inertial>
      <mass value="1"/>
      <inertia ixx="1.0" ixy="0.0" ixz="0.0" iyy="0.5" iyz="0.0" izz="1.0"/>
    </inertial>
  </link>
  <gazebo reference="shoulder_pitch_link">
    <material>Gazebo/White</material>
  </gazebo>
  <joint name="elbow_roll_joint" type="revolute">
    <parent link="shoulder_pitch_link"/>
    <child link="elbow_roll_link"/>
    <origin rpy="1.570795 0 0" xyz="-0.002 -0.05 0.37"/>
    <axis xyz="1 0 0"/>
    <limit effort="300" lower="-1.87" upper="1.5" velocity="1"/>
    <dynamics damping="50" friction="1"/>
  </joint>
  <!--elbow roll link-->
  <link name="elbow_roll_link">
    <visual>
      <origin rpy="0 -1.570795 0" xyz="0.0 0.0 0.0"/>
      <geometry>
        <cylinder length="0.06" radius="0.02"/>
      </geometry>
      <material name="Black"/>
    </visual>
    <collision>
      <origin rpy="0 -1.570795 0" xyz="0.0 0.0 0.0"/>
      <geometry>
        <cylinder length="0.06" radius="0.02"/>
      </geometry>
    </collision>
    <inertial>
      <mass value="1"/>
      <inertia ixx="1.0" ixy="0.0" ixz="0.0" iyy="0.5" iyz="0.0" izz="1.0"/>
    </inertial>
  </link>
  <gazebo reference="elbow_roll_link">
    <material>Gazebo/Black</material>
  </gazebo>
  <joint name="elbow_pitch_joint" type="fixed">
    <parent link="elbow_roll_link"/>
    <child link="elbow_pitch_link"/>
    <origin rpy="0.0 0.0 0.0" xyz="0 0 0.2"/>
    <axis xyz="1 0 0"/>
    <limit effort="300" lower="-1.5953400194" upper="1.93281579274" velocity="1"/>
    <dynamics damping="50" friction="1"/>
  </joint>
  <!--elbow_pitch_link-->
  <link name="elbow_pitch_link">
    <visual>
      <origin rpy="0 1.570795 0" xyz="0 0 0"/>
      <geometry>
        <box size="0.4 0.04 0.04"/>
      </geometry>
      <material name="Red"/>
    </visual>
  </link>
  <gazebo reference="elbow_pitch_link">
    <material>Gazebo/Red</material>
  </gazebo>
  <!-- Transmissions for ROS Control -->
  <transmission name="tran1">
    <type>transmission_interface/SimpleTransmssion</type>
    <joint name="shoulder_pan_joint">
      <hardwareInterface>hardware_interface/PositionJointInterface</hardwareInterface>
    </joint>
    <actuator name="motor1">
      <hardwareInterface>hardware_interface/PositionJointInterface</hardwareInterface>
      <mechanicalReduction>1</mechanicalReduction>
    </actuator>
  </transmission>
  <transmission name="tran1">
    <type>transmission_interface/SimpleTransmssion</type>
    <joint name="shoulder_pitch_joint">
      <hardwareInterface>hardware_interface/PositionJointInterface</hardwareInterface>
    </joint>
    <actuator name="motor1">
      <hardwareInterface>hardware_interface/PositionJointInterface</hardwareInterface>
      <mechanicalReduction>1</mechanicalReduction>
    </actuator>
  </transmission>
  <transmission name="tran1">
    <type>transmission_interface/SimpleTransmssion</type>
    <joint name="elbow_roll_joint">
      <hardwareInterface>hardware_interface/PositionJointInterface</hardwareInterface>
    </joint>
    <actuator name="motor1">
      <hardwareInterface>hardware_interface/PositionJointInterface</hardwareInterface>
      <mechanicalReduction>1</mechanicalReduction>
    </actuator>
  </transmission>
  <!--xacro:transmission_block joint_name="elbow_pitch_joint"/-->
  <gazebo>
    <plugin filename="libgazebo_ros_control.so" name="gazebo_ros_control">
      <robotNamespace>/Finder_arm</robotNamespace>
      <robotSimType>gazebo_ros_control/DefaultRobotHWSim</robotSimType>
      <legacyModeNS>True</legacyModeNS>
    </plugin>
  </gazebo>
</robot>
